Workbook
Name cohort_size: 'Inputs'!$B$6
Name start_age: 'Inputs'!$B$7
Name p_detect_symptoms: 'Inputs'!$B$11
Name p_progression: 'Inputs'!$B$12
Name p_cure_early: 'Inputs'!$B$13
Name p_death_advanced: 'Inputs'!$B$14
Name screen_participation: 'Inputs'!$B$18
Name screen_sensitivity: 'Inputs'!$B$19
Name screen_specificity: 'Inputs'!$B$20
Name cost_screen_test: 'Inputs'!$B$24
Name cost_followup_test: 'Inputs'!$B$25
Name cost_early_treatment: 'Inputs'!$B$26
Name cost_advanced_year: 'Inputs'!$B$27
Name u_healthy: 'Inputs'!$B$31
Name u_early: 'Inputs'!$B$32
Name u_advanced: 'Inputs'!$B$33
Name disc_costs: 'Inputs'!$B$37
Name disc_effects: 'Inputs'!$B$38
Name wtp: 'Inputs'!$B$39
Name age_band_label: 'Inputs'!$A$43:$A$54
Name age_band_start: 'Inputs'!$B$43:$B$54
Name p_background_death: 'Inputs'!$C$43:$C$54
Name p_cancer_onset: 'Inputs'!$D$43:$D$54
Name strategy_name: 'Inputs'!$A$59:$A$61
Name strategy_screens: 'Inputs'!$C$59:$C$61
Name strategy_first_age: 'Inputs'!$D$59:$D$61
Name strategy_last_age: 'Inputs'!$E$59:$E$61
Name strategy_description: 'Inputs'!$F$59:$F$61
Name input_check: 'Inputs'!$B$3
Name out_check: 'Results'!$B$3
Name out_strategy: 'Results'!$B$8:$B$10
Name out_cost: 'Results'!$C$8:$C$10
Name out_qalys: 'Results'!$D$8:$D$10
Name out_life_years: 'Results'!$E$8:$E$10
Name out_life_years_undiscounted: 'Results'!$F$8:$F$10
Name out_nmb: 'Results'!$G$8:$G$10
Name out_best: 'Results'!$B$4
Name out_icer_vs_first: 'Results'!$F$14:$F$16
Name out_frontier_strategy: 'Results'!$B$20:$B$22
Name out_frontier_status: 'Results'!$E$20:$E$22
Name out_frontier_icer: 'Results'!$I$20:$I$22
Name out_cancer_deaths: 'Results'!$G$33:$G$35
Name out_diagnoses: 'Results'!$D$33:$E$35
Name out_incidence: 'Results'!$C$40:$E$51

Sheet Start here
B1: Cancer screening: a teaching cost-effectiveness model
B2: A Markov cohort model of a hypothetical cancer that you can read, change and break. All numbers are illustrative: they are not real data and the results should not be used for real decisions.
B4: What this workbook does
B5: It follows a group of 100,000 people (a cohort) from age 40, one year per row, for 60 years. Each year it counts how many people are healthy, have an early or an advanced cancer, or have died. It does this for three strategies: no screening, and a yearly screening test from age 50 or from age 45 until 74. The cancer, the test and the treatments are generic: they stand for any cancer that can be found early by screening and is easier to cure when it is. For each strategy it adds up the costs and the quality-adjusted life years (QALYs), and then compares the strategies as a cost-effectiveness analysis (CEA) does.
B7: How to use it
B8: Step 1 | C8: Look at the diagram below and read "How it works" to understand the model.
B9: Step 2 | C9: Change any blue cell on yellow in the Inputs sheet, for example the price of the test.
B10: Step 3 | C10: Look at Results and Charts: everything recalculates at once.
B11: Step 4 | C11: Open a Trace sheet to follow, row by row, how each year is calculated from the year before. Hover over a column header for an explanation, or click a cell to read its formula.
B12: Step 5 | C12: Use the Transition matrix sheet to see the matrix of any year and how it moves the cohort.
B13: Step 6 | C13: To go back to the original values, copy the "Base case" column of Inputs into the "Value" column.
B15: Colour code
B16: 0.25 | C16: An input: change it freely. Data validation stops values that make no sense.
B17: 0.25 | C17: A calculation (formula) in the same sheet. Do not type over it.
B18: 0.25 | C18: A value taken from another sheet.
B19: OK | C19: A check. It shows CHECK or PROBLEM when an input makes the model impossible.
B21: The sheets
B22: Start here | C22: This page.
B23: How it works | C23: The model step by step: states, transition probabilities, costs, QALYs, discounting and how strategies are compared.
B24: Inputs | C24: Every number the model uses, with what it means. The only sheet you need to edit.
B25: Trace 1, 2, 3 | C25: The Markov trace of each strategy: one row per year, with the probabilities, the transition matrix, the people in each state, the events, costs and QALYs of that year.
B26: Transition matrix | C26: The transition matrix of a chosen year, shown as a matrix.
B27: Results | C27: Costs, QALYs, ICERs, the efficiency frontier, the cost-effective strategy, cancer outcomes and incidence by age.
B28: Charts | C28: Cost-effectiveness plane, incidence by age and the cohort over time.
B29: Interface | C29: For programs that run the workbook: which cells are its inputs and results. You do not need it.
B31: The model
B50: Key ideas
B51: Markov cohort model | C51: Instead of simulating people one by one, it tracks how many people of a group are in each health state, and moves them between states once per cycle.
B52: Cycle | C52: The time step of the model: here one year, so one row of a Trace sheet.
B53: Transition probability | C53: The chance of moving from one state to another in one cycle, for example from Healthy to Early cancer.
B54: Transition matrix | C54: All the transition probabilities in a table: one row per state now, one column per state a year later. Each row adds up to 1. Here it changes with age and with screening, so each row of a Trace sheet has its own.
B55: Markov trace | C55: The number of people in each state, cycle after cycle.
B56: Utility and QALY | C56: A utility weights a year by its quality of life (1 = full health, 0 = dead). A quality-adjusted life year (QALY) is a year lived times its utility.
B57: Discounting | C57: Costs and health in the future are valued less than now. A value in year t is multiplied by 1 / (1 + rate)^t.
B58: ICER | C58: Incremental cost-effectiveness ratio: the extra cost of a strategy divided by the extra QALYs it gives, compared with an alternative. "€ per QALY gained".
B59: Willingness to pay | C59: The threshold: the most a health system pays per QALY gained. A strategy with an ICER below it is considered cost-effective.
B60: Dominance | C60: A strategy is dominated if another one is cheaper and gives more QALYs. It is extendedly dominated if a mix of two others would beat it.
B61: Efficiency frontier | C61: The strategies that are not dominated, sorted by cost. ICERs are calculated along it, each strategy against the previous one.
B62: Net monetary benefit | C62: QALYs x willingness to pay - cost. The strategy with the highest one is the cost-effective choice; it always agrees with the frontier.
B64: Things to try
...

Sheet How it works
B1: How the model works
B3: 1. The health states
B4: Healthy | C4: No cancer. Everyone starts here.
B5: Early cancer | C5: A small cancer that causes few or no symptoms and has not been diagnosed. This is the state screening is looking for: treated now, it is usually cured.
B6: Advanced cancer | C6: A cancer that has grown. It causes symptoms, so it is diagnosed, and it is treated every year, but people with it have a high chance of dying of it.
B7: Dead | C7: From any cause. Nobody leaves this state (it is "absorbing").
B9: 2. What happens in one year
B10: At the start of each year the model counts the people in each state. Those people determine the costs and QALYs of the year. Then, during the year, people move between states according to the transition probabilities of that year, which gives the people at the start of the next year. The probabilities depend on age (from the table in Inputs) and on whether the strategy screens at that age.
B11: Within a year, death from other causes comes first; the cancer events happen to those who survive it. That is why many formulas start with (1 - death from other causes).
B13: 3. The transition probabilities
B14: Probability that an early cancer is detected in a year: detected = 1 - (1 - p_detect_symptoms) x (1 - screened x screen_sensitivity) where screened = screen_participation if the strategy screens at this age, and 0 otherwise. An early cancer stays hidden only if symptoms do not reveal it and screening misses it, so the chance of being found is 1 minus the chance that both miss it. This is the only place where screening changes the course of the disease.
B15: Write p_bg for the probability of death from other causes at this age and p_onset for the probability of cancer starting. Then:
B16: Healthy → Early cancer | C16: (1 - p_bg) x p_onset
B17: Healthy → Dead | C17: p_bg
B18: Healthy → Healthy | C18: 1 - the two above
B19: Early → Healthy | C19: (1 - p_bg) x detected x p_cure_early
B20: Early → Advanced | C20: (1 - p_bg) x [detected x (1 - p_cure_early) + (1 - detected) x p_progression]
B21: Early → Dead | C21: p_bg
B22: Early → Early | C22: (1 - p_bg) x (1 - detected) x (1 - p_progression)
B23: Advanced → Dead | C23: 1 - (1 - p_bg) x (1 - p_death_advanced)
B24: Advanced → Advanced | C24: 1 - the one above
B25: Dead → Dead | C25: 1
B26: Each row of the matrix adds up to 1. The orange columns of the Trace sheets hold these values for every year, and the Transition matrix sheet shows them as a matrix.
B28: 4. Moving the cohort
B29: People next year in a state = sum over this year's states of (people in that state x probability of moving from it to this state). For example: Healthy next year = Healthy x (Healthy → Healthy) + Early x (Early → Healthy) In matrix terms, the row of people next year is the row of people this year multiplied by the transition matrix. The green columns of the Trace sheets do exactly this.
B31: 5. Costs
B32: Screening | C32: Tests: everyone alive without a diagnosed cancer (Healthy + Early) x the probability of being screened x cost_screen_test. Follow-up tests after a positive screen: screened healthy people x (1 - specificity) + screened people with early cancer x sensitivity, x cost_followup_test.
B33: Early treatment | C33: Early cancers diagnosed in the year x cost_early_treatment (paid once).
B34: Advanced treatment | C34: People with advanced cancer x cost_advanced_year (paid every year).
B36: 6. Health outcomes
B37: Life years | C37: Each person alive at the start of a year lives that year.
B38: QALYs | C38: Healthy x u_healthy + Early x u_early + Advanced x u_advanced.
B39: Discounting | C39: The cost and QALYs of year t (t = 0 the first year) are multiplied by 1 / (1 + rate)^t, with the rates of Inputs, section 6.
B40: Per person | C40: Results divides the totals of the cohort by the cohort size.
B42: 7. Comparing the strategies
B43: ICER | C43: (cost of A - cost of B) / (QALYs of A - QALYs of B): the price of each extra QALY that A buys compared with B.
B44: Frontier | C44: Sort by cost. Remove strategies that are dominated (another costs less and gives more QALYs) and extendedly dominated (its ICER is higher than that of the next, more expensive strategy). Compare each remaining strategy with the previous one.
B45: Decision | C45: The cost-effective strategy is the most effective one on the frontier whose ICER is below the willingness to pay. Equivalently, the one with the highest net monetary benefit (QALYs x willingness to pay - cost).
B47: 8. Shortcuts this model takes
B48: • | C48: One-year cycles. Costs and QALYs are counted for the people at the start of each year, with no half-cycle correction, so the model slightly undercounts the time people spend in a state before leaving it.
...

Sheet Inputs
A1: Inputs
A2: Change the blue cells on yellow. Everything else in the workbook recalculates. The "Base case" column keeps the original values so you can go back to them.
A3: Input check | B3: =IF(AND(MIN(B6)>=1,MAX(B6)<=10000000,MIN(B7)>=40,MAX(B7)<=80,MIN(B11)>=0,MAX(B11)<=1,MIN(B12)>=0,MAX(B12)<=1,MIN(B13)>=0,MAX(B13)<=1,MIN(B14)>=0,MAX(B14)<=1,MIN(B18)>=0,MAX(B18)<=1,MIN(B19)>=0,MAX(B19)<=1,MIN(B20)>=0,MAX(B20)<=1,MIN(B24)>=0,MIN(B25)>=0,MIN(B26)>=0,MIN(B27)>=0,MIN(B31)>=0,MAX(B31)<=1,MIN(B32)>=0,MAX(B32)<=1,MIN(B33)>=0,MAX(B33)<=1,MIN(B37)>=0,MAX(B37)<=1,MIN(B38)>=0,MAX(B38)<=1,MIN(B39)>=0,MIN(C43:D54)>=0,MAX(C43:D54)<=1),"OK","CHECK") -> OK | C3: CHECK means a value is outside its valid range (for example a probability above 100%).
A4: 1. The cohort
A5: Parameter | B5: Value | C5: Unit | D5: Base case | E5: Name in formulas | F5: What it means
A6: Number of people in the cohort | B6: 100000 | C6: people | D6: 100000 | E6: cohort_size | F6: How many people are followed. Results are reported per person, so this only changes the scale of counts like cancer deaths. 100,000 makes counts easy to read.
A7: Age of the cohort at the start | B7: 40 | C7: years | D7: 40 | E7: start_age | F7: Everyone starts healthy at this age and is followed for 60 yearly cycles (a lifetime horizon). Ages above 99 use the 95-99 probabilities.
A9: 2. Natural history of the cancer (probabilities per year)
A10: Parameter | B10: Value | C10: Unit | D10: Base case | E10: Name in formulas | F10: What it means
A11: Early cancer found because of symptoms | B11: 0.1 | C11: per year | D11: 0.1 | E11: p_detect_symptoms | F11: Chance that an undiagnosed early cancer causes symptoms and is diagnosed in a year, without screening. The probability of developing cancer depends on age and is in table 7 below.
A12: Undiagnosed early cancer becomes advanced | B12: 0.25 | C12: per year | D12: 0.25 | E12: p_progression | F12: Chance that an early cancer that was not found this year grows into advanced cancer. Then it is diagnosed, because advanced cancer causes symptoms.
A13: Treatment of an early cancer cures it | B13: 0.9 | C13: probability | D13: 0.9 | E13: p_cure_early | F13: Chance that treating a diagnosed early cancer cures it (the person goes back to Healthy). If it does not, the person moves to Advanced cancer.
A14: Death from advanced cancer | B14: 0.25 | C14: per year | D14: 0.25 | E14: p_death_advanced | F14: Chance of dying from the cancer in a year with advanced cancer, on top of other causes.
A16: 3. Screening test
A17: Parameter | B17: Value | C17: Unit | D17: Base case | E17: Name in formulas | F17: What it means
A18: People who take the test when invited | B18: 0.6 | C18: proportion | D18: 0.6 | E18: screen_participation | F18: Share of the eligible people (alive and not diagnosed with advanced cancer) who do the test each year, in the years that a strategy screens.
A19: Sensitivity for early cancer | B19: 0.7 | C19: proportion | D19: 0.7 | E19: screen_sensitivity | F19: Chance that the test is positive when the person has an early cancer. A positive test leads to a follow-up diagnostic test (for example a biopsy or a scan), which confirms the cancer.
A20: Specificity | B20: 0.93 | C20: proportion | D20: 0.93 | E20: screen_specificity | F20: Chance that the test is negative when the person has no cancer. The rest (1 - specificity) are false positives: healthy people sent to a follow-up test that finds nothing.
A22: 4. Costs (€)
A23: Parameter | B23: Value | C23: Unit | D23: Base case | E23: Name in formulas | F23: What it means
A24: One screening test | B24: 30 | C24: € per test | D24: 30 | E24: cost_screen_test | F24: Cost of inviting a person, doing one screening test and reading the result.
A25: One follow-up diagnostic test after a positive screen | B25: 1000 | C25: € per follow-up test | D25: 1000 | E25: cost_followup_test | F25: Paid for every positive screening test, true or false, to confirm or rule out the cancer.
A26: Treating an early cancer | B26: 15000 | C26: € per cancer, once | D26: 15000 | E26: cost_early_treatment | F26: One-off cost of treating an early cancer, paid in the year it is diagnosed.
A27: Treating advanced cancer | B27: 20000 | C27: € per person per year | D27: 20000 | E27: cost_advanced_year | F27: Cost of treatment and care for each year spent with advanced cancer.
A29: 5. Quality of life (utility weights: 0 = dead, 1 = full health)
A30: Parameter | B30: Value | C30: Unit | D30: Base case | E30: Name in formulas | F30: What it means
A31: A year without cancer | B31: 0.9 | C31: utility | D31: 0.9 | E31: u_healthy | F31: Average quality of life of adults without cancer. It is below 1 because people of these ages have other health problems too.
A32: A year with undiagnosed early cancer | B32: 0.85 | C32: utility | D32: 0.85 | E32: u_early | F32: Early cancer causes few symptoms, so it is only slightly below Healthy.
A33: A year with advanced cancer | B33: 0.55 | C33: utility | D33: 0.55 | E33: u_advanced | F33: Symptoms and treatment side effects lower quality of life considerably.
A35: 6. Discounting and the decision rule
A36: Parameter | B36: Value | C36: Unit | D36: Base case | E36: Name in formulas | F36: What it means
A37: Discount rate for costs | B37: 0.03 | C37: per year | D37: 0.03 | E37: disc_costs | F37: Costs in the future count for less than costs today: a cost in year t is multiplied by 1 / (1 + rate)^t.
A38: Discount rate for health effects | B38: 0.03 | C38: per year | D38: 0.03 | E38: disc_effects | F38: Same for life years and QALYs. Some countries use a different rate for health than for costs.
A39: Willingness to pay per QALY gained | B39: 25000 | C39: € per QALY | D39: 25000 | E39: wtp | F39: The most the health system is willing to pay for one extra QALY (the cost-effectiveness threshold). It decides which strategy is "cost-effective".
A41: 7. Probabilities that depend on age (per year)
A42: Age group | B42: From age | C42: Death from other causes | D42: Cancer starts (healthy people) | E42: Base: other causes | F42: Base: cancer starts
A43: 40-44 | B43: 40 | C43: 0.0015 | D43: 0.00025 | E43: 0.0015 | F43: 0.00025
A44: 45-49 | B44: 45 | C44: 0.0023 | D44: 0.00035 | E44: 0.0023 | F44: 0.00035
A45: 50-54 | B45: 50 | C45: 0.0036 | D45: 0.00055 | E45: 0.0036 | F45: 0.00055
A46: 55-59 | B46: 55 | C46: 0.0055 | D46: 0.0008 | E46: 0.0055 | F46: 0.0008
...

Sheet Trace 1
A1: ="Markov trace of strategy 1: "&INDEX(strategy_name,1) -> Markov trace of strategy 1: No screening
A2: Strategy number | B2: 1
A3: Screens? | B3: =INDEX(strategy_screens,$B$2) -> No | D3: First age screened | E3: =INDEX(strategy_first_age,$B$2) -> 50 | G3: Last age screened | H3: =INDEX(strategy_last_age,$B$2) -> 74
A4: Each row is one year (one cycle). The people in each state this year (green block) come from last year's row: last year's people x last year's transition matrix (orange block). Hover over a column header to see what it does, or click a cell to read its formula.
A5: Costs and QALYs of a year are counted for the people in each state at the start of that year. Row 8 adds up all the years; Results uses those totals.
A6: Time | D6: This year's probabilities | I6: Transition matrix of this year (row by row) | R6: Cohort at the start of the year (people) | W6: Events during the year (people) | AB6: Screening (number) | AD6: Costs of the year (€, not discounted) | AH6: Health of the year (not discounted) | AJ6: Discounting | AL6: Discounted (what the results use) | AO6: Check
A7: Cycle (years since start) | B7: Age | C7: Age group | D7: Death from other causes | E7: Cancer starts (if healthy) | F7: Screening offered? (1 = yes) | G7: Screened this year | H7: Early cancer detected this year | I7: Healthy → Healthy | J7: Healthy → Early | K7: Healthy → Dead | L7: Early → Healthy | M7: Early → Early | N7: Early → Advanced | O7: Early → Dead | P7: Advanced → Advanced | Q7: Advanced → Dead | R7: Healthy | S7: Early cancer | T7: Advanced cancer | U7: Dead | V7: Alive | W7: New cancers | X7: Diagnosed early | Y7: Diagnosed advanced | Z7: All diagnoses | AA7: Cancer deaths | AB7: Screening tests | AC7: Follow-up tests | AD7: Screening | AE7: Early treatment | AF7: Advanced treatment | AG7: Total cost | AH7: Life years | AI7: QALYs | AJ7: Discount factor (costs) | AK7: Discount factor (health) | AL7: Discounted cost | AM7: Discounted QALYs | AN7: Discounted life years | AO7: Check
A8: All years | W8: =SUM(W9:W68) -> 4685.5874 | X8: =SUM(X9:X68) -> 1260.0438 | Y8: =SUM(Y9:Y68) -> 2835.0985 | Z8: =SUM(Z9:Z68) -> 4095.1423 | AA8: =SUM(AA9:AA68) -> 2449.2068 | AB8: =SUM(AB9:AB68) -> 0 | AC8: =SUM(AC9:AC68) -> 0 | AD8: =SUM(AD9:AD68) -> 0 | ... AI8: =SUM(AI9:AI68) -> 3745575.1 | AL8: =SUM(AL9:AL68) -> 88982654 | AM8: =SUM(AM9:AM68) -> 2121701.1 | AN8: =SUM(AN9:AN68) -> 2359324.4 | AO8: =IF(COUNTIF(AO9:AO68,"OK")=60,"OK","CHECK") -> OK
A9: 0 | B9: =start_age+A9 -> 40 | C9: =INDEX(age_band_label,MATCH(B9,age_band_start,1)) -> 40-44 | D9: =INDEX(p_background_death,MATCH(B9,age_band_start,1)) -> 0.0015 | E9: =INDEX(p_cancer_onset,MATCH(B9,age_band_start,1)) -> 0.00025 | F9: =IF(AND($B$3="Yes",B9>=$E$3,B9<=$H$3),1,0) -> 0 | G9: =F9*screen_participation -> 0 | H9: =1-(1-p_detect_symptoms)*(1-G9*screen_sensitivity) -> 0.1 | I9: =1-J9-K9 -> 0.99825038 | J9: =(1-D9)*E9 -> 0.000249625 | K9: =D9 -> 0.0015 | L9: =(1-D9)*H9*p_cure_early -> 0.089865 | M9: =(1-D9)*(1-H9)*(1-p_progression) -> 0.6739875 | N9: =(1-D9)*(H9*(1-p_cure_early)+(1-H9)*p_progression) -> 0.2346475 | O9: =D9 -> 0.0015 | P9: =1-Q9 -> 0.748875 | Q9: =1-(1-D9)*(1-p_death_advanced) -> 0.251125 | R9: =cohort_size -> 100000 | S9: 0 | T9: 0 | U9: 0 | V9: =R9+S9+T9 -> 100000 | W9: =R9*J9 -> 24.9625 | X9: =S9*(1-D9)*H9 -> 0 | Y9: =S9*(1-D9)*(1-H9)*p_progression -> 0 | Z9: =X9+Y9 -> 0 | AA9: =T9*(1-D9)*p_death_advanced -> 0 | AB9: =(R9+S9)*G9 -> 0 | AC9: =G9*(R9*(1-screen_specificity)+S9*screen_sensitivity) -> 0 | AD9: =AB9*cost_screen_test+AC9*cost_followup_test -> 0 | AE9: =X9*cost_early_treatment -> 0 | AF9: =T9*cost_advanced_year -> 0 | AG9: =AD9+AE9+AF9 -> 0 | AH9: =V9 -> 100000 | AI9: =R9*u_healthy+S9*u_early+T9*u_advanced -> 90000 | AJ9: =1/(1+disc_costs)^A9 -> 1 | AK9: =1/(1+disc_effects)^A9 -> 1 | AL9: =AG9*AJ9 -> 0 | AM9: =AI9*AK9 -> 90000 | AN9: =AH9*AK9 -> 100000 | AO9: =IF(AND(ABS(V9+U9-cohort_size)<0.000001*cohort_size,MIN(I9:Q9)>=0,MAX(I9:Q9)<=1),"OK","CHECK") -> OK
A10: =A9+1 -> 1 | B10: =start_age+A10 -> 41 | C10: =INDEX(age_band_label,MATCH(B10,age_band_start,1)) -> 40-44 | D10: =INDEX(p_background_death,MATCH(B10,age_band_start,1)) -> 0.0015 | E10: =INDEX(p_cancer_onset,MATCH(B10,age_band_start,1)) -> 0.00025 | F10: =IF(AND($B$3="Yes",B10>=$E$3,B10<=$H$3),1,0) -> 0 | G10: =F10*screen_participation -> 0 | H10: =1-(1-p_detect_symptoms)*(1-G10*screen_sensitivity) -> 0.1 | I10: =1-J10-K10 -> 0.99825038 | J10: =(1-D10)*E10 -> 0.000249625 | K10: =D10 -> 0.0015 | L10: =(1-D10)*H10*p_cure_early -> 0.089865 | M10: =(1-D10)*(1-H10)*(1-p_progression) -> 0.6739875 | N10: =(1-D10)*(H10*(1-p_cure_early)+(1-H10)*p_progression) -> 0.2346475 | O10: =D10 -> 0.0015 | P10: =1-Q10 -> 0.748875 | Q10: =1-(1-D10)*(1-p_death_advanced) -> 0.251125 | R10: =R9*I9+S9*L9 -> 99825.038 | S10: =R9*J9+S9*M9 -> 24.9625 | T10: =S9*N9+T9*P9 -> 0 | U10: =U9+R9*K9+S9*O9+T9*Q9 -> 150 | V10: =R10+S10+T10 -> 99850 | W10: =R10*J10 -> 24.918825 | X10: =S10*(1-D10)*H10 -> 2.4925056 | Y10: =S10*(1-D10)*(1-H10)*p_progression -> 5.6081377 | Z10: =X10+Y10 -> 8.1006433 | AA10: =T10*(1-D10)*p_death_advanced -> 0 | AB10: =(R10+S10)*G10 -> 0 | AC10: =G10*(R10*(1-screen_specificity)+S10*screen_sensitivity) -> 0 | AD10: =AB10*cost_screen_test+AC10*cost_followup_test -> 0 | AE10: =X10*cost_early_treatment -> 37387.584 | AF10: =T10*cost_advanced_year -> 0 | AG10: =AD10+AE10+AF10 -> 37387.584 | AH10: =V10 -> 99850 | AI10: =R10*u_healthy+S10*u_early+T10*u_advanced -> 89863.752 | AJ10: =1/(1+disc_costs)^A10 -> 0.97087379 | AK10: =1/(1+disc_effects)^A10 -> 0.97087379 | AL10: =AG10*AJ10 -> 36298.626 | AM10: =AI10*AK10 -> 87246.361 | AN10: =AH10*AK10 -> 96941.748 | AO10: =IF(AND(ABS(V10+U10-cohort_size)<0.000001*cohort_size,MIN(I10:Q10)>=0,MAX(I10:Q10)<=1),"OK","CHECK") -> OK
A11: =A10+1 -> 2 | B11: =start_age+A11 -> 42 | C11: =INDEX(age_band_label,MATCH(B11,age_band_start,1)) -> 40-44 | D11: =INDEX(p_background_death,MATCH(B11,age_band_start,1)) -> 0.0015 | E11: =INDEX(p_cancer_onset,MATCH(B11,age_band_start,1)) -> 0.00025 | F11: =IF(AND($B$3="Yes",B11>=$E$3,B11<=$H$3),1,0) -> 0 | G11: =F11*screen_participation -> 0 | H11: =1-(1-p_detect_symptoms)*(1-G11*screen_sensitivity) -> 0.1 | I11: =1-J11-K11 -> 0.99825038 | J11: =(1-D11)*E11 -> 0.000249625 | K11: =D11 -> 0.0015 | L11: =(1-D11)*H11*p_cure_early -> 0.089865 | M11: =(1-D11)*(1-H11)*(1-p_progression) -> 0.6739875 | N11: =(1-D11)*(H11*(1-p_cure_early)+(1-H11)*p_progression) -> 0.2346475 | O11: =D11 -> 0.0015 | P11: =1-Q11 -> 0.748875 | Q11: =1-(1-D11)*(1-p_death_advanced) -> 0.251125 | R11: =R10*I10+S10*L10 -> 99652.624 | S11: =R10*J10+S10*M10 -> 41.743238 | T11: =S10*N10+T10*P10 -> 5.8573882 | U11: =U10+R10*K10+S10*O10+T10*Q10 -> 299.775 | V11: =R11+S11+T11 -> 99700.225 | W11: =R11*J11 -> 24.875786 | X11: =S11*(1-D11)*H11 -> 4.1680623 | Y11: =S11*(1-D11)*(1-H11)*p_progression -> 9.3781402 | Z11: =X11+Y11 -> 13.546203 | AA11: =T11*(1-D11)*p_death_advanced -> 1.4621505 | AB11: =(R11+S11)*G11 -> 0 | AC11: =G11*(R11*(1-screen_specificity)+S11*screen_sensitivity) -> 0 | AD11: =AB11*cost_screen_test+AC11*cost_followup_test -> 0 | AE11: =X11*cost_early_treatment -> 62520.935 | AF11: =T11*cost_advanced_year -> 117147.76 | AG11: =AD11+AE11+AF11 -> 179668.7 | AH11: =V11 -> 99700.225 | AI11: =R11*u_healthy+S11*u_early+T11*u_advanced -> 89726.065 | AJ11: =1/(1+disc_costs)^A11 -> 0.94259591 | AK11: =1/(1+disc_effects)^A11 -> 0.94259591 | AL11: =AG11*AJ11 -> 169354.98 | AM11: =AI11*AK11 -> 84575.422 | AN11: =AH11*AK11 -> 93977.024 | AO11: =IF(AND(ABS(V11+U11-cohort_size)<0.000001*cohort_size,MIN(I11:Q11)>=0,MAX(I11:Q11)<=1),"OK","CHECK") -> OK
A12: =A11+1 -> 3 | B12: =start_age+A12 -> 43 | C12: =INDEX(age_band_label,MATCH(B12,age_band_start,1)) -> 40-44 | D12: =INDEX(p_background_death,MATCH(B12,age_band_start,1)) -> 0.0015 | E12: =INDEX(p_cancer_onset,MATCH(B12,age_band_start,1)) -> 0.00025 | F12: =IF(AND($B$3="Yes",B12>=$E$3,B12<=$H$3),1,0) -> 0 | G12: =F12*screen_participation -> 0 | H12: =1-(1-p_detect_symptoms)*(1-G12*screen_sensitivity) -> 0.1 | I12: =1-J12-K12 -> 0.99825038 | J12: =(1-D12)*E12 -> 0.000249625 | K12: =D12 -> 0.0015 | L12: =(1-D12)*H12*p_cure_early -> 0.089865 | M12: =(1-D12)*(1-H12)*(1-p_progression) -> 0.6739875 | N12: =(1-D12)*(H12*(1-p_cure_early)+(1-H12)*p_progression) -> 0.2346475 | O12: =D12 -> 0.0015 | P12: =1-Q12 -> 0.748875 | Q12: =1-(1-D12)*(1-p_death_advanced) -> 0.251125 | R12: =R11*I11+S11*L11 -> 99482.021 | S12: =R11*J11+S11*M11 -> 53.010207 | T12: =S11*N11+T11*P11 -> 14.181398 | U12: =U11+R11*K11+S11*O11+T11*Q11 -> 450.78749 | V12: =R12+S12+T12 -> 99549.213 | W12: =R12*J12 -> 24.833199 | X12: =S12*(1-D12)*H12 -> 5.2930692 | Y12: =S12*(1-D12)*(1-H12)*p_progression -> 11.909406 | Z12: =X12+Y12 -> 17.202475 | AA12: =T12*(1-D12)*p_death_advanced -> 3.5400315 | AB12: =(R12+S12)*G12 -> 0 | AC12: =G12*(R12*(1-screen_specificity)+S12*screen_sensitivity) -> 0 | AD12: =AB12*cost_screen_test+AC12*cost_followup_test -> 0 | AE12: =X12*cost_early_treatment -> 79396.037 | AF12: =T12*cost_advanced_year -> 283627.96 | AG12: =AD12+AE12+AF12 -> 363024 | AH12: =V12 -> 99549.213 | AI12: =R12*u_healthy+S12*u_early+T12*u_advanced -> 89586.677 | AJ12: =1/(1+disc_costs)^A12 -> 0.91514166 | AK12: =1/(1+disc_effects)^A12 -> 0.91514166 | AL12: =AG12*AJ12 -> 332218.38 | AM12: =AI12*AK12 -> 81984.5 | AN12: =AH12*AK12 -> 91101.632 | AO12: =IF(AND(ABS(V12+U12-cohort_size)<0.000001*cohort_size,MIN(I12:Q12)>=0,MAX(I12:Q12)<=1),"OK","CHECK") -> OK
A13: =A12+1 -> 4 | B13: =start_age+A13 -> 44 | C13: =INDEX(age_band_label,MATCH(B13,age_band_start,1)) -> 40-44 | D13: =INDEX(p_background_death,MATCH(B13,age_band_start,1)) -> 0.0015 | E13: =INDEX(p_cancer_onset,MATCH(B13,age_band_start,1)) -> 0.00025 | F13: =IF(AND($B$3="Yes",B13>=$E$3,B13<=$H$3),1,0) -> 0 | G13: =F13*screen_participation -> 0 | H13: =1-(1-p_detect_symptoms)*(1-G13*screen_sensitivity) -> 0.1 | I13: =1-J13-K13 -> 0.99825038 | J13: =(1-D13)*E13 -> 0.000249625 | K13: =D13 -> 0.0015 | L13: =(1-D13)*H13*p_cure_early -> 0.089865 | M13: =(1-D13)*(1-H13)*(1-p_progression) -> 0.6739875 | N13: =(1-D13)*(H13*(1-p_cure_early)+(1-H13)*p_progression) -> 0.2346475 | O13: =D13 -> 0.0015 | P13: =1-Q13 -> 0.748875 | Q13: =1-(1-D13)*(1-p_death_advanced) -> 0.251125 | R13: =R12*I12+S12*L12 -> 99312.728 | S13: =R12*J12+S12*M12 -> 60.561416 | T13: =S12*N12+T12*P12 -> 23.058807 | U13: =U12+R12*K12+S12*O12+T12*Q12 -> 603.65134 | V13: =R13+S13+T13 -> 99396.349 | W13: =R13*J13 -> 24.79094 | X13: =S13*(1-D13)*H13 -> 6.0470574 | Y13: =S13*(1-D13)*(1-H13)*p_progression -> 13.605879 | Z13: =X13+Y13 -> 19.652937 | AA13: =T13*(1-D13)*p_death_advanced -> 5.7560547 | AB13: =(R13+S13)*G13 -> 0 | AC13: =G13*(R13*(1-screen_specificity)+S13*screen_sensitivity) -> 0 | AD13: =AB13*cost_screen_test+AC13*cost_followup_test -> 0 | AE13: =X13*cost_early_treatment -> 90705.861 | AF13: =T13*cost_advanced_year -> 461176.14 | AG13: =AD13+AE13+AF13 -> 551882 | AH13: =V13 -> 99396.349 | AI13: =R13*u_healthy+S13*u_early+T13*u_advanced -> 89445.615 | AJ13: =1/(1+disc_costs)^A13 -> 0.88848705 | AK13: =1/(1+disc_effects)^A13 -> 0.88848705 | AL13: =AG13*AJ13 -> 490340.01 | AM13: =AI13*AK13 -> 79471.271 | AN13: =AH13*AK13 -> 88312.368 | AO13: =IF(AND(ABS(V13+U13-cohort_size)<0.000001*cohort_size,MIN(I13:Q13)>=0,MAX(I13:Q13)<=1),"OK","CHECK") -> OK
A14: =A13+1 -> 5 | B14: =start_age+A14 -> 45 | C14: =INDEX(age_band_label,MATCH(B14,age_band_start,1)) -> 45-49 | D14: =INDEX(p_background_death,MATCH(B14,age_band_start,1)) -> 0.0023 | E14: =INDEX(p_cancer_onset,MATCH(B14,age_band_start,1)) -> 0.00035 | F14: =IF(AND($B$3="Yes",B14>=$E$3,B14<=$H$3),1,0) -> 0 | G14: =F14*screen_participation -> 0 | H14: =1-(1-p_detect_symptoms)*(1-G14*screen_sensitivity) -> 0.1 | I14: =1-J14-K14 -> 0.99735081 | J14: =(1-D14)*E14 -> 0.000349195 | K14: =D14 -> 0.0023 | L14: =(1-D14)*H14*p_cure_early -> 0.089793 | M14: =(1-D14)*(1-H14)*(1-p_progression) -> 0.6734475 | N14: =(1-D14)*(H14*(1-p_cure_early)+(1-H14)*p_progression) -> 0.2344595 | O14: =D14 -> 0.0023 | P14: =1-Q14 -> 0.748275 | Q14: =1-(1-D14)*(1-p_death_advanced) -> 0.251725 | R14: =R13*I13+S13*L13 -> 99144.411 | S14: =R13*J13+S13*M13 -> 65.608577 | T14: =S13*N13+T13*P13 -> 31.478749 | U14: =U13+R13*K13+S13*O13+T13*Q13 -> 758.50192 | V14: =R14+S14+T14 -> 99241.498 | W14: =R14*J14 -> 34.620733 | X14: =S14*(1-D14)*H14 -> 6.5457678 | Y14: =S14*(1-D14)*(1-H14)*p_progression -> 14.727977 | Z14: =X14+Y14 -> 21.273745 | AA14: =T14*(1-D14)*p_death_advanced -> 7.851587 | AB14: =(R14+S14)*G14 -> 0 | AC14: =G14*(R14*(1-screen_specificity)+S14*screen_sensitivity) -> 0 | AD14: =AB14*cost_screen_test+AC14*cost_followup_test -> 0 | AE14: =X14*cost_early_treatment -> 98186.517 | AF14: =T14*cost_advanced_year -> 629574.98 | AG14: =AD14+AE14+AF14 -> 727761.5 | AH14: =V14 -> 99241.498 | AI14: =R14*u_healthy+S14*u_early+T14*u_advanced -> 89303.05 | AJ14: =1/(1+disc_costs)^A14 -> 0.86260878 | AK14: =1/(1+disc_effects)^A14 -> 0.86260878 | AL14: =AG14*AJ14 -> 627773.46 | AM14: =AI14*AK14 -> 77033.596 | AN14: =AH14*AK14 -> 85606.588 | AO14: =IF(AND(ABS(V14+U14-cohort_size)<0.000001*cohort_size,MIN(I14:Q14)>=0,MAX(I14:Q14)<=1),"OK","CHECK") -> OK
A15: =A14+1 -> 6 | B15: =start_age+A15 -> 46 | C15: =INDEX(age_band_label,MATCH(B15,age_band_start,1)) -> 45-49 | D15: =INDEX(p_background_death,MATCH(B15,age_band_start,1)) -> 0.0023 | E15: =INDEX(p_cancer_onset,MATCH(B15,age_band_start,1)) -> 0.00035 | F15: =IF(AND($B$3="Yes",B15>=$E$3,B15<=$H$3),1,0) -> 0 | G15: =F15*screen_participation -> 0 | H15: =1-(1-p_detect_symptoms)*(1-G15*screen_sensitivity) -> 0.1 | I15: =1-J15-K15 -> 0.99735081 | J15: =(1-D15)*E15 -> 0.000349195 | K15: =D15 -> 0.0023 | L15: =(1-D15)*H15*p_cure_early -> 0.089793 | M15: =(1-D15)*(1-H15)*(1-p_progression) -> 0.6734475 | N15: =(1-D15)*(H15*(1-p_cure_early)+(1-H15)*p_progression) -> 0.2344595 | O15: =D15 -> 0.0023 | P15: =1-Q15 -> 0.748275 | Q15: =1-(1-D15)*(1-p_death_advanced) -> 0.251725 | R15: =R14*I14+S14*L14 -> 98887.649 | S15: =R14*J14+S14*M14 -> 78.804665 | T15: =S14*N14+T14*P14 -> 38.937315 | U15: =U14+R14*K14+S14*O14+T14*Q14 -> 994.60895 | V15: =R15+S15+T15 -> 99005.391 | W15: =R15*J15 -> 34.531073 | X15: =S15*(1-D15)*H15 -> 7.8623414 | Y15: =S15*(1-D15)*(1-H15)*p_progression -> 17.690268 | Z15: =X15+Y15 -> 25.55261 | AA15: =T15*(1-D15)*p_death_advanced -> 9.7119398 | AB15: =(R15+S15)*G15 -> 0 | AC15: =G15*(R15*(1-screen_specificity)+S15*screen_sensitivity) -> 0 | AD15: =AB15*cost_screen_test+AC15*cost_followup_test -> 0 | AE15: =X15*cost_early_treatment -> 117935.12 | AF15: =T15*cost_advanced_year -> 778746.3 | AG15: =AD15+AE15+AF15 -> 896681.42 | AH15: =V15 -> 99005.391 | AI15: =R15*u_healthy+S15*u_early+T15*u_advanced -> 89087.284 | AJ15: =1/(1+disc_costs)^A15 -> 0.83748426 | AK15: =1/(1+disc_effects)^A15 -> 0.83748426 | AL15: =AG15*AJ15 -> 750956.58 | AM15: =AI15*AK15 -> 74609.198 | AN15: =AH15*AK15 -> 82915.456 | AO15: =IF(AND(ABS(V15+U15-cohort_size)<0.000001*cohort_size,MIN(I15:Q15)>=0,MAX(I15:Q15)<=1),"OK","CHECK") -> OK
A16: =A15+1 -> 7 | B16: =start_age+A16 -> 47 | C16: =INDEX(age_band_label,MATCH(B16,age_band_start,1)) -> 45-49 | D16: =INDEX(p_background_death,MATCH(B16,age_band_start,1)) -> 0.0023 | E16: =INDEX(p_cancer_onset,MATCH(B16,age_band_start,1)) -> 0.00035 | F16: =IF(AND($B$3="Yes",B16>=$E$3,B16<=$H$3),1,0) -> 0 | G16: =F16*screen_participation -> 0 | H16: =1-(1-p_detect_symptoms)*(1-G16*screen_sensitivity) -> 0.1 | I16: =1-J16-K16 -> 0.99735081 | J16: =(1-D16)*E16 -> 0.000349195 | K16: =D16 -> 0.0023 | L16: =(1-D16)*H16*p_cure_early -> 0.089793 | M16: =(1-D16)*(1-H16)*(1-p_progression) -> 0.6734475 | N16: =(1-D16)*(H16*(1-p_cure_early)+(1-H16)*p_progression) -> 0.2344595 | O16: =D16 -> 0.0023 | P16: =1-Q16 -> 0.748275 | Q16: =1-(1-D16)*(1-p_death_advanced) -> 0.251725 | R16: =R15*I15+S15*L15 -> 98632.753 | S16: =R15*J15+S15*M15 -> 87.601877 | T16: =S15*N15+T15*P15 -> 47.612322 | U16: =U15+R15*K15+S15*O15+T15*Q15 -> 1232.0333 | V16: =R16+S16+T16 -> 98767.967 | W16: =R16*J16 -> 34.442064 | X16: =S16*(1-D16)*H16 -> 8.7400393 | Y16: =S16*(1-D16)*(1-H16)*p_progression -> 19.665088 | Z16: =X16+Y16 -> 28.405128 | AA16: =T16*(1-D16)*p_death_advanced -> 11.875703 | AB16: =(R16+S16)*G16 -> 0 | AC16: =G16*(R16*(1-screen_specificity)+S16*screen_sensitivity) -> 0 | AD16: =AB16*cost_screen_test+AC16*cost_followup_test -> 0 | AE16: =X16*cost_early_treatment -> 131100.59 | AF16: =T16*cost_advanced_year -> 952246.44 | AG16: =AD16+AE16+AF16 -> 1083347 | AH16: =V16 -> 98767.967 | AI16: =R16*u_healthy+S16*u_early+T16*u_advanced -> 88870.126 | AJ16: =1/(1+disc_costs)^A16 -> 0.81309151 | AK16: =1/(1+disc_effects)^A16 -> 0.81309151 | AL16: =AG16*AJ16 -> 880860.27 | AM16: =AI16*AK16 -> 72259.545 | AN16: =AH16*AK16 -> 80307.395 | AO16: =IF(AND(ABS(V16+U16-cohort_size)<0.000001*cohort_size,MIN(I16:Q16)>=0,MAX(I16:Q16)<=1),"OK","CHECK") -> OK
A17: =A16+1 -> 8 | B17: =start_age+A17 -> 48 | C17: =INDEX(age_band_label,MATCH(B17,age_band_start,1)) -> 45-49 | D17: =INDEX(p_background_death,MATCH(B17,age_band_start,1)) -> 0.0023 | E17: =INDEX(p_cancer_onset,MATCH(B17,age_band_start,1)) -> 0.00035 | F17: =IF(AND($B$3="Yes",B17>=$E$3,B17<=$H$3),1,0) -> 0 | G17: =F17*screen_participation -> 0 | H17: =1-(1-p_detect_symptoms)*(1-G17*screen_sensitivity) -> 0.1 | I17: =1-J17-K17 -> 0.99735081 | J17: =(1-D17)*E17 -> 0.000349195 | K17: =D17 -> 0.0023 | L17: =(1-D17)*H17*p_cure_early -> 0.089793 | M17: =(1-D17)*(1-H17)*(1-p_progression) -> 0.6734475 | N17: =(1-D17)*(H17*(1-p_cure_early)+(1-H17)*p_progression) -> 0.2344595 | O17: =D17 -> 0.0023 | P17: =1-Q17 -> 0.748275 | Q17: =1-(1-D17)*(1-p_death_advanced) -> 0.251725 | R17: =R16*I16+S16*L16 -> 98379.321 | S17: =R16*J16+S16*M16 -> 93.437329 | T17: =S16*N16+T16*P16 -> 56.166202 | U17: =U16+R16*K16+S16*O16+T16*Q16 -> 1471.0753 | V17: =R17+S17+T17 -> 98528.925 | W17: =R17*J17 -> 34.353567 | X17: =S17*(1-D17)*H17 -> 9.3222423 | Y17: =S17*(1-D17)*(1-H17)*p_progression -> 20.975045 | Z17: =X17+Y17 -> 30.297288 | AA17: =T17*(1-D17)*p_death_advanced -> 14.009255 | AB17: =(R17+S17)*G17 -> 0 | AC17: =G17*(R17*(1-screen_specificity)+S17*screen_sensitivity) -> 0 | AD17: =AB17*cost_screen_test+AC17*cost_followup_test -> 0 | AE17: =X17*cost_early_treatment -> 139833.64 | AF17: =T17*cost_advanced_year -> 1123324 | AG17: =AD17+AE17+AF17 -> 1263157.7 | AH17: =V17 -> 98528.925 | AI17: =R17*u_healthy+S17*u_early+T17*u_advanced -> 88651.702 | AJ17: =1/(1+disc_costs)^A17 -> 0.78940923 | AK17: =1/(1+disc_effects)^A17 -> 0.78940923 | AL17: =AG17*AJ17 -> 997148.34 | AM17: =AI17*AK17 -> 69982.472 | AN17: =AH17*AK17 -> 77779.643 | AO17: =IF(AND(ABS(V17+U17-cohort_size)<0.000001*cohort_size,MIN(I17:Q17)>=0,MAX(I17:Q17)<=1),"OK","CHECK") -> OK
A18: =A17+1 -> 9 | B18: =start_age+A18 -> 49 | C18: =INDEX(age_band_label,MATCH(B18,age_band_start,1)) -> 45-49 | D18: =INDEX(p_background_death,MATCH(B18,age_band_start,1)) -> 0.0023 | E18: =INDEX(p_cancer_onset,MATCH(B18,age_band_start,1)) -> 0.00035 | F18: =IF(AND($B$3="Yes",B18>=$E$3,B18<=$H$3),1,0) -> 0 | G18: =F18*screen_participation -> 0 | H18: =1-(1-p_detect_symptoms)*(1-G18*screen_sensitivity) -> 0.1 | I18: =1-J18-K18 -> 0.99735081 | J18: =(1-D18)*E18 -> 0.000349195 | K18: =D18 -> 0.0023 | L18: =(1-D18)*H18*p_cure_early -> 0.089793 | M18: =(1-D18)*(1-H18)*(1-p_progression) -> 0.6734475 | N18: =(1-D18)*(H18*(1-p_cure_early)+(1-H18)*p_progression) -> 0.2344595 | O18: =D18 -> 0.0023 | P18: =1-Q18 -> 0.748275 | Q18: =1-(1-D18)*(1-p_death_advanced) -> 0.251725 | R18: =R17*I17+S17*L17 -> 98127.085 | S18: =R17*J17+S17*M17 -> 97.278703 | T18: =S17*N17+T17*P17 -> 63.935035 | U18: =U17+R17*K17+S17*O17+T17*Q17 -> 1711.7011 | V18: =R18+S18+T18 -> 98288.299 | W18: =R18*J18 -> 34.265488 | X18: =S18*(1-D18)*H18 -> 9.7054962 | Y18: =S18*(1-D18)*(1-H18)*p_progression -> 21.837366 | Z18: =X18+Y18 -> 31.542863 | AA18: =T18*(1-D18)*p_death_advanced -> 15.946996 | AB18: =(R18+S18)*G18 -> 0 | AC18: =G18*(R18*(1-screen_specificity)+S18*screen_sensitivity) -> 0 | AD18: =AB18*cost_screen_test+AC18*cost_followup_test -> 0 | AE18: =X18*cost_early_treatment -> 145582.44 | AF18: =T18*cost_advanced_year -> 1278700.7 | AG18: =AD18+AE18+AF18 -> 1424283.1 | AH18: =V18 -> 98288.299 | AI18: =R18*u_healthy+S18*u_early+T18*u_advanced -> 88432.228 | AJ18: =1/(1+disc_costs)^A18 -> 0.76641673 | AK18: =1/(1+disc_effects)^A18 -> 0.76641673 | AL18: =AG18*AJ18 -> 1091594.4 | AM18: =AI18*AK18 -> 67775.939 | AN18: =AH18*AK18 -> 75329.797 | AO18: =IF(AND(ABS(V18+U18-cohort_size)<0.000001*cohort_size,MIN(I18:Q18)>=0,MAX(I18:Q18)<=1),"OK","CHECK") -> OK
A19: =A18+1 -> 10 | B19: =start_age+A19 -> 50 | C19: =INDEX(age_band_label,MATCH(B19,age_band_start,1)) -> 50-54 | D19: =INDEX(p_background_death,MATCH(B19,age_band_start,1)) -> 0.0036 | E19: =INDEX(p_cancer_onset,MATCH(B19,age_band_start,1)) -> 0.00055 | F19: =IF(AND($B$3="Yes",B19>=$E$3,B19<=$H$3),1,0) -> 0 | G19: =F19*screen_participation -> 0 | H19: =1-(1-p_detect_symptoms)*(1-G19*screen_sensitivity) -> 0.1 | I19: =1-J19-K19 -> 0.99585198 | J19: =(1-D19)*E19 -> 0.00054802 | K19: =D19 -> 0.0036 | L19: =(1-D19)*H19*p_cure_early -> 0.089676 | M19: =(1-D19)*(1-H19)*(1-p_progression) -> 0.67257 | N19: =(1-D19)*(H19*(1-p_cure_early)+(1-H19)*p_progression) -> 0.234154 | O19: =D19 -> 0.0036 | P19: =1-Q19 -> 0.7473 | Q19: =1-(1-D19)*(1-p_death_advanced) -> 0.2527 | R19: =R18*I18+S18*L18 -> 97875.862 | S19: =R18*J18+S18*M18 -> 99.777587 | T19: =S18*N18+T18*P18 -> 70.648904 | U19: =U18+R18*K18+S18*O18+T18*Q18 -> 1953.7112 | V19: =R19+S19+T19 -> 98046.289 | W19: =R19*J19 -> 53.63793 | X19: =S19*(1-D19)*H19 -> 9.9418387 | Y19: =S19*(1-D19)*(1-H19)*p_progression -> 22.369137 | Z19: =X19+Y19 -> 32.310976 | AA19: =T19*(1-D19)*p_death_advanced -> 17.598642 | AB19: =(R19+S19)*G19 -> 0 | AC19: =G19*(R19*(1-screen_specificity)+S19*screen_sensitivity) -> 0 | AD19: =AB19*cost_screen_test+AC19*cost_followup_test -> 0 | AE19: =X19*cost_early_treatment -> 149127.58 | AF19: =T19*cost_advanced_year -> 1412978.1 | AG19: =AD19+AE19+AF19 -> 1562105.7 | AH19: =V19 -> 98046.289 | AI19: =R19*u_healthy+S19*u_early+T19*u_advanced -> 88211.944 | AJ19: =1/(1+disc_costs)^A19 -> 0.74409391 | AK19: =1/(1+disc_effects)^A19 -> 0.74409391 | AL19: =AG19*AJ19 -> 1162353.3 | AM19: =AI19*AK19 -> 65637.971 | AN19: =AH19*AK19 -> 72955.647 | AO19: =IF(AND(ABS(V19+U19-cohort_size)<0.000001*cohort_size,MIN(I19:Q19)>=0,MAX(I19:Q19)<=1),"OK","CHECK") -> OK
A20: =A19+1 -> 11 | B20: =start_age+A20 -> 51 | C20: =INDEX(age_band_label,MATCH(B20,age_band_start,1)) -> 50-54 | D20: =INDEX(p_background_death,MATCH(B20,age_band_start,1)) -> 0.0036 | E20: =INDEX(p_cancer_onset,MATCH(B20,age_band_start,1)) -> 0.00055 | F20: =IF(AND($B$3="Yes",B20>=$E$3,B20<=$H$3),1,0) -> 0 | G20: =F20*screen_participation -> 0 | H20: =1-(1-p_detect_symptoms)*(1-G20*screen_sensitivity) -> 0.1 | I20: =1-J20-K20 -> 0.99585198 | J20: =(1-D20)*E20 -> 0.00054802 | K20: =D20 -> 0.0036 | L20: =(1-D20)*H20*p_cure_early -> 0.089676 | M20: =(1-D20)*(1-H20)*(1-p_progression) -> 0.67257 | N20: =(1-D20)*(H20*(1-p_cure_early)+(1-H20)*p_progression) -> 0.234154 | O20: =D20 -> 0.0036 | P20: =1-Q20 -> 0.7473 | Q20: =1-(1-D20)*(1-p_death_advanced) -> 0.2527 | R20: =R19*I19+S19*L19 -> 97478.819 | S20: =R19*J19+S19*M19 -> 120.74534 | T20: =S19*N19+T19*P19 -> 76.159247 | U20: =U19+R19*K19+S19*O19+T19*Q19 -> 2324.2765 | V20: =R20+S20+T20 -> 97675.724 | W20: =R20*J20 -> 53.420342 | X20: =S20*(1-D20)*H20 -> 12.031066 | Y20: =S20*(1-D20)*(1-H20)*p_progression -> 27.069898 | Z20: =X20+Y20 -> 39.100964 | AA20: =T20*(1-D20)*p_death_advanced -> 18.971268 | AB20: =(R20+S20)*G20 -> 0 | AC20: =G20*(R20*(1-screen_specificity)+S20*screen_sensitivity) -> 0 | AD20: =AB20*cost_screen_test+AC20*cost_followup_test -> 0 | AE20: =X20*cost_early_treatment -> 180465.99 | AF20: =T20*cost_advanced_year -> 1523184.9 | AG20: =AD20+AE20+AF20 -> 1703650.9 | AH20: =V20 -> 97675.724 | AI20: =R20*u_healthy+S20*u_early+T20*u_advanced -> 87875.458 | AJ20: =1/(1+disc_costs)^A20 -> 0.72242128 | AK20: =1/(1+disc_effects)^A20 -> 0.72242128 | AL20: =AG20*AJ20 -> 1230753.7 | AM20: =AI20*AK20 -> 63483.101 | AN20: =AH20*AK20 -> 70563.021 | AO20: =IF(AND(ABS(V20+U20-cohort_size)<0.000001*cohort_size,MIN(I20:Q20)>=0,MAX(I20:Q20)<=1),"OK","CHECK") -> OK
A21: =A20+1 -> 12 | B21: =start_age+A21 -> 52 | C21: =INDEX(age_band_label,MATCH(B21,age_band_start,1)) -> 50-54 | D21: =INDEX(p_background_death,MATCH(B21,age_band_start,1)) -> 0.0036 | E21: =INDEX(p_cancer_onset,MATCH(B21,age_band_start,1)) -> 0.00055 | F21: =IF(AND($B$3="Yes",B21>=$E$3,B21<=$H$3),1,0) -> 0 | G21: =F21*screen_participation -> 0 | H21: =1-(1-p_detect_symptoms)*(1-G21*screen_sensitivity) -> 0.1 | I21: =1-J21-K21 -> 0.99585198 | J21: =(1-D21)*E21 -> 0.00054802 | K21: =D21 -> 0.0036 | L21: =(1-D21)*H21*p_cure_early -> 0.089676 | M21: =(1-D21)*(1-H21)*(1-p_progression) -> 0.67257 | N21: =(1-D21)*(H21*(1-p_cure_early)+(1-H21)*p_progression) -> 0.234154 | O21: =D21 -> 0.0036 | P21: =1-Q21 -> 0.7473 | Q21: =1-(1-D21)*(1-p_death_advanced) -> 0.2527 | R21: =R20*I20+S20*L20 -> 97085.303 | S21: =R20*J20+S20*M20 -> 134.63004 | T21: =S20*N20+T20*P20 -> 85.18681 | U21: =U20+R20*K20+S20*O20+T20*Q20 -> 2694.8803 | V21: =R21+S21+T21 -> 97305.12 | W21: =R21*J21 -> 53.204688 | X21: =S21*(1-D21)*H21 -> 13.414537 | Y21: =S21*(1-D21)*(1-H21)*p_progression -> 30.182708 | Z21: =X21+Y21 -> 43.597245 | AA21: =T21*(1-D21)*p_death_advanced -> 21.220034 | AB21: =(R21+S21)*G21 -> 0 | AC21: =G21*(R21*(1-screen_specificity)+S21*screen_sensitivity) -> 0 | AD21: =AB21*cost_screen_test+AC21*cost_followup_test -> 0 | AE21: =X21*cost_early_treatment -> 201218.05 | AF21: =T21*cost_advanced_year -> 1703736.2 | AG21: =AD21+AE21+AF21 -> 1904954.3 | AH21: =V21 -> 97305.12 | AI21: =R21*u_healthy+S21*u_early+T21*u_advanced -> 87538.061 | AJ21: =1/(1+disc_costs)^A21 -> 0.70137988 | AK21: =1/(1+disc_effects)^A21 -> 0.70137988 | AL21: =AG21*AJ21 -> 1336096.6 | AM21: =AI21*AK21 -> 61397.435 | AN21: =AH21*AK21 -> 68247.853 | AO21: =IF(AND(ABS(V21+U21-cohort_size)<0.000001*cohort_size,MIN(I21:Q21)>=0,MAX(I21:Q21)<=1),"OK","CHECK") -> OK
... A68: =A67+1 -> 59 | B68: =start_age+A68 -> 99 | C68: =INDEX(age_band_label,MATCH(B68,age_band_start,1)) -> 95-99 | D68: =INDEX(p_background_death,MATCH(B68,age_band_start,1)) -> 0.29 | E68: =INDEX(p_cancer_onset,MATCH(B68,age_band_start,1)) -> 0.0024 | F68: =IF(AND($B$3="Yes",B68>=$E$3,B68<=$H$3),1,0) -> 0 | G68: =F68*screen_participation -> 0 | H68: =1-(1-p_detect_symptoms)*(1-G68*screen_sensitivity) -> 0.1 | I68: =1-J68-K68 -> 0.708296 | J68: =(1-D68)*E68 -> 0.001704 | K68: =D68 -> 0.29 | L68: =(1-D68)*H68*p_cure_early -> 0.0639 | M68: =(1-D68)*(1-H68)*(1-p_progression) -> 0.47925 | N68: =(1-D68)*(H68*(1-p_cure_early)+(1-H68)*p_progression) -> 0.16685 | O68: =D68 -> 0.29 | P68: =1-Q68 -> 0.5325 | Q68: =1-(1-D68)*(1-p_death_advanced) -> 0.4675 | R68: =R67*I67+S67*L67 -> 2354.6896 | S68: =R67*J67+S67*M67 -> 17.48015 | T68: =S67*N67+T67*P67 -> 16.500728 | U68: =U67+R67*K67+S67*O67+T67*Q67 -> 97611.33 | V68: =R68+S68+T68 -> 2388.6705 | W68: =R68*J68 -> 4.0123911 | X68: =S68*(1-D68)*H68 -> 1.2410907 | Y68: =S68*(1-D68)*(1-H68)*p_progression -> 2.792454 | Z68: =X68+Y68 -> 4.0335446 | AA68: =T68*(1-D68)*p_death_advanced -> 2.9288793 | AB68: =(R68+S68)*G68 -> 0 | AC68: =G68*(R68*(1-screen_specificity)+S68*screen_sensitivity) -> 0 | AD68: =AB68*cost_screen_test+AC68*cost_followup_test -> 0 | AE68: =X68*cost_early_treatment -> 18616.36 | AF68: =T68*cost_advanced_year -> 330014.56 | AG68: =AD68+AE68+AF68 -> 348630.92 | AH68: =V68 -> 2388.6705 | AI68: =R68*u_healthy+S68*u_early+T68*u_advanced -> 2143.1542 | AJ68: =1/(1+disc_costs)^A68 -> 0.17482508 | AK68: =1/(1+disc_effects)^A68 -> 0.17482508 | AL68: =AG68*AJ68 -> 60949.43 | AM68: =AI68*AK68 -> 374.6771 | AN68: =AH68*AK68 -> 417.59951 | AO68: =IF(AND(ABS(V68+U68-cohort_size)<0.000001*cohort_size,MIN(I68:Q68)>=0,MAX(I68:Q68)<=1),"OK","CHECK") -> OK

Sheet Trace 2
A1: ="Markov trace of strategy 2: "&INDEX(strategy_name,2) -> Markov trace of strategy 2: Screening 50-74
A2: Strategy number | B2: 2
A3: Screens? | B3: =INDEX(strategy_screens,$B$2) -> Yes | D3: First age screened | E3: =INDEX(strategy_first_age,$B$2) -> 50 | G3: Last age screened | H3: =INDEX(strategy_last_age,$B$2) -> 74
A4: Each row is one year (one cycle). The people in each state this year (green block) come from last year's row: last year's people x last year's transition matrix (orange block). Hover over a column header to see what it does, or click a cell to read its formula.
A5: Costs and QALYs of a year are counted for the people in each state at the start of that year. Row 8 adds up all the years; Results uses those totals.
A6: Time | D6: This year's probabilities | I6: Transition matrix of this year (row by row) | R6: Cohort at the start of the year (people) | W6: Events during the year (people) | AB6: Screening (number) | AD6: Costs of the year (€, not discounted) | AH6: Health of the year (not discounted) | AJ6: Discounting | AL6: Discounted (what the results use) | AO6: Check
A7: Cycle (years since start) | B7: Age | C7: Age group | D7: Death from other causes | E7: Cancer starts (if healthy) | F7: Screening offered? (1 = yes) | G7: Screened this year | H7: Early cancer detected this year | I7: Healthy → Healthy | J7: Healthy → Early | K7: Healthy → Dead | L7: Early → Healthy | M7: Early → Early | N7: Early → Advanced | O7: Early → Dead | P7: Advanced → Advanced | Q7: Advanced → Dead | R7: Healthy | S7: Early cancer | T7: Advanced cancer | U7: Dead | V7: Alive | W7: New cancers | X7: Diagnosed early | Y7: Diagnosed advanced | Z7: All diagnoses | AA7: Cancer deaths | AB7: Screening tests | AC7: Follow-up tests | AD7: Screening | AE7: Early treatment | AF7: Advanced treatment | AG7: Total cost | AH7: Life years | AI7: QALYs | AJ7: Discount factor (costs) | AK7: Discount factor (health) | AL7: Discounted cost | AM7: Discounted QALYs | AN7: Discounted life years | AO7: Check
A8: All years | W8: =SUM(W9:W68) -> 4721.9771 | X8: =SUM(X9:X68) -> 2395.4324 | Y8: =SUM(Y9:Y68) -> 1784.3822 | Z8: =SUM(Z9:Z68) -> 4179.8146 | AA8: =SUM(AA9:AA68) -> 1590.0681 | AB8: =SUM(AB9:AB68) -> 1353579.3 | AC8: =SUM(AC9:AC68) -> 96210.544 | AD8: =SUM(AD9:AD68) -> 1.3681792e+08 | ... AI8: =SUM(AI9:AI68) -> 3759390.8 | AL8: =SUM(AL9:AL68) -> 1.4155654e+08 | AM8: =SUM(AM9:AM68) -> 2126468.9 | AN8: =SUM(AN9:AN68) -> 2363956.9 | AO8: =IF(COUNTIF(AO9:AO68,"OK")=60,"OK","CHECK") -> OK
A9: 0 | B9: =start_age+A9 -> 40 | C9: =INDEX(age_band_label,MATCH(B9,age_band_start,1)) -> 40-44 | D9: =INDEX(p_background_death,MATCH(B9,age_band_start,1)) -> 0.0015 | E9: =INDEX(p_cancer_onset,MATCH(B9,age_band_start,1)) -> 0.00025 | F9: =IF(AND($B$3="Yes",B9>=$E$3,B9<=$H$3),1,0) -> 0 | G9: =F9*screen_participation -> 0 | H9: =1-(1-p_detect_symptoms)*(1-G9*screen_sensitivity) -> 0.1 | I9: =1-J9-K9 -> 0.99825038 | J9: =(1-D9)*E9 -> 0.000249625 | K9: =D9 -> 0.0015 | L9: =(1-D9)*H9*p_cure_early -> 0.089865 | M9: =(1-D9)*(1-H9)*(1-p_progression) -> 0.6739875 | N9: =(1-D9)*(H9*(1-p_cure_early)+(1-H9)*p_progression) -> 0.2346475 | O9: =D9 -> 0.0015 | P9: =1-Q9 -> 0.748875 | Q9: =1-(1-D9)*(1-p_death_advanced) -> 0.251125 | R9: =cohort_size -> 100000 | S9: 0 | T9: 0 | U9: 0 | V9: =R9+S9+T9 -> 100000 | W9: =R9*J9 -> 24.9625 | X9: =S9*(1-D9)*H9 -> 0 | Y9: =S9*(1-D9)*(1-H9)*p_progression -> 0 | Z9: =X9+Y9 -> 0 | AA9: =T9*(1-D9)*p_death_advanced -> 0 | AB9: =(R9+S9)*G9 -> 0 | AC9: =G9*(R9*(1-screen_specificity)+S9*screen_sensitivity) -> 0 | AD9: =AB9*cost_screen_test+AC9*cost_followup_test -> 0 | AE9: =X9*cost_early_treatment -> 0 | AF9: =T9*cost_advanced_year -> 0 | AG9: =AD9+AE9+AF9 -> 0 | AH9: =V9 -> 100000 | AI9: =R9*u_healthy+S9*u_early+T9*u_advanced -> 90000 | AJ9: =1/(1+disc_costs)^A9 -> 1 | AK9: =1/(1+disc_effects)^A9 -> 1 | AL9: =AG9*AJ9 -> 0 | AM9: =AI9*AK9 -> 90000 | AN9: =AH9*AK9 -> 100000 | AO9: =IF(AND(ABS(V9+U9-cohort_size)<0.000001*cohort_size,MIN(I9:Q9)>=0,MAX(I9:Q9)<=1),"OK","CHECK") -> OK
A10: =A9+1 -> 1 | B10: =start_age+A10 -> 41 | C10: =INDEX(age_band_label,MATCH(B10,age_band_start,1)) -> 40-44 | D10: =INDEX(p_background_death,MATCH(B10,age_band_start,1)) -> 0.0015 | E10: =INDEX(p_cancer_onset,MATCH(B10,age_band_start,1)) -> 0.00025 | F10: =IF(AND($B$3="Yes",B10>=$E$3,B10<=$H$3),1,0) -> 0 | G10: =F10*screen_participation -> 0 | H10: =1-(1-p_detect_symptoms)*(1-G10*screen_sensitivity) -> 0.1 | I10: =1-J10-K10 -> 0.99825038 | J10: =(1-D10)*E10 -> 0.000249625 | K10: =D10 -> 0.0015 | L10: =(1-D10)*H10*p_cure_early -> 0.089865 | M10: =(1-D10)*(1-H10)*(1-p_progression) -> 0.6739875 | N10: =(1-D10)*(H10*(1-p_cure_early)+(1-H10)*p_progression) -> 0.2346475 | O10: =D10 -> 0.0015 | P10: =1-Q10 -> 0.748875 | Q10: =1-(1-D10)*(1-p_death_advanced) -> 0.251125 | R10: =R9*I9+S9*L9 -> 99825.038 | S10: =R9*J9+S9*M9 -> 24.9625 | T10: =S9*N9+T9*P9 -> 0 | U10: =U9+R9*K9+S9*O9+T9*Q9 -> 150 | V10: =R10+S10+T10 -> 99850 | W10: =R10*J10 -> 24.918825 | X10: =S10*(1-D10)*H10 -> 2.4925056 | Y10: =S10*(1-D10)*(1-H10)*p_progression -> 5.6081377 | Z10: =X10+Y10 -> 8.1006433 | AA10: =T10*(1-D10)*p_death_advanced -> 0 | AB10: =(R10+S10)*G10 -> 0 | AC10: =G10*(R10*(1-screen_specificity)+S10*screen_sensitivity) -> 0 | AD10: =AB10*cost_screen_test+AC10*cost_followup_test -> 0 | AE10: =X10*cost_early_treatment -> 37387.584 | AF10: =T10*cost_advanced_year -> 0 | AG10: =AD10+AE10+AF10 -> 37387.584 | AH10: =V10 -> 99850 | AI10: =R10*u_healthy+S10*u_early+T10*u_advanced -> 89863.752 | AJ10: =1/(1+disc_costs)^A10 -> 0.97087379 | AK10: =1/(1+disc_effects)^A10 -> 0.97087379 | AL10: =AG10*AJ10 -> 36298.626 | AM10: =AI10*AK10 -> 87246.361 | AN10: =AH10*AK10 -> 96941.748 | AO10: =IF(AND(ABS(V10+U10-cohort_size)<0.000001*cohort_size,MIN(I10:Q10)>=0,MAX(I10:Q10)<=1),"OK","CHECK") -> OK
A11: =A10+1 -> 2 | B11: =start_age+A11 -> 42 | C11: =INDEX(age_band_label,MATCH(B11,age_band_start,1)) -> 40-44 | D11: =INDEX(p_background_death,MATCH(B11,age_band_start,1)) -> 0.0015 | E11: =INDEX(p_cancer_onset,MATCH(B11,age_band_start,1)) -> 0.00025 | F11: =IF(AND($B$3="Yes",B11>=$E$3,B11<=$H$3),1,0) -> 0 | G11: =F11*screen_participation -> 0 | H11: =1-(1-p_detect_symptoms)*(1-G11*screen_sensitivity) -> 0.1 | I11: =1-J11-K11 -> 0.99825038 | J11: =(1-D11)*E11 -> 0.000249625 | K11: =D11 -> 0.0015 | L11: =(1-D11)*H11*p_cure_early -> 0.089865 | M11: =(1-D11)*(1-H11)*(1-p_progression) -> 0.6739875 | N11: =(1-D11)*(H11*(1-p_cure_early)+(1-H11)*p_progression) -> 0.2346475 | O11: =D11 -> 0.0015 | P11: =1-Q11 -> 0.748875 | Q11: =1-(1-D11)*(1-p_death_advanced) -> 0.251125 | R11: =R10*I10+S10*L10 -> 99652.624 | S11: =R10*J10+S10*M10 -> 41.743238 | T11: =S10*N10+T10*P10 -> 5.8573882 | U11: =U10+R10*K10+S10*O10+T10*Q10 -> 299.775 | V11: =R11+S11+T11 -> 99700.225 | W11: =R11*J11 -> 24.875786 | X11: =S11*(1-D11)*H11 -> 4.1680623 | Y11: =S11*(1-D11)*(1-H11)*p_progression -> 9.3781402 | Z11: =X11+Y11 -> 13.546203 | AA11: =T11*(1-D11)*p_death_advanced -> 1.4621505 | AB11: =(R11+S11)*G11 -> 0 | AC11: =G11*(R11*(1-screen_specificity)+S11*screen_sensitivity) -> 0 | AD11: =AB11*cost_screen_test+AC11*cost_followup_test -> 0 | AE11: =X11*cost_early_treatment -> 62520.935 | AF11: =T11*cost_advanced_year -> 117147.76 | AG11: =AD11+AE11+AF11 -> 179668.7 | AH11: =V11 -> 99700.225 | AI11: =R11*u_healthy+S11*u_early+T11*u_advanced -> 89726.065 | AJ11: =1/(1+disc_costs)^A11 -> 0.94259591 | AK11: =1/(1+disc_effects)^A11 -> 0.94259591 | AL11: =AG11*AJ11 -> 169354.98 | AM11: =AI11*AK11 -> 84575.422 | AN11: =AH11*AK11 -> 93977.024 | AO11: =IF(AND(ABS(V11+U11-cohort_size)<0.000001*cohort_size,MIN(I11:Q11)>=0,MAX(I11:Q11)<=1),"OK","CHECK") -> OK
A12: =A11+1 -> 3 | B12: =start_age+A12 -> 43 | C12: =INDEX(age_band_label,MATCH(B12,age_band_start,1)) -> 40-44 | D12: =INDEX(p_background_death,MATCH(B12,age_band_start,1)) -> 0.0015 | E12: =INDEX(p_cancer_onset,MATCH(B12,age_band_start,1)) -> 0.00025 | F12: =IF(AND($B$3="Yes",B12>=$E$3,B12<=$H$3),1,0) -> 0 | G12: =F12*screen_participation -> 0 | H12: =1-(1-p_detect_symptoms)*(1-G12*screen_sensitivity) -> 0.1 | I12: =1-J12-K12 -> 0.99825038 | J12: =(1-D12)*E12 -> 0.000249625 | K12: =D12 -> 0.0015 | L12: =(1-D12)*H12*p_cure_early -> 0.089865 | M12: =(1-D12)*(1-H12)*(1-p_progression) -> 0.6739875 | N12: =(1-D12)*(H12*(1-p_cure_early)+(1-H12)*p_progression) -> 0.2346475 | O12: =D12 -> 0.0015 | P12: =1-Q12 -> 0.748875 | Q12: =1-(1-D12)*(1-p_death_advanced) -> 0.251125 | R12: =R11*I11+S11*L11 -> 99482.021 | S12: =R11*J11+S11*M11 -> 53.010207 | T12: =S11*N11+T11*P11 -> 14.181398 | U12: =U11+R11*K11+S11*O11+T11*Q11 -> 450.78749 | V12: =R12+S12+T12 -> 99549.213 | W12: =R12*J12 -> 24.833199 | X12: =S12*(1-D12)*H12 -> 5.2930692 | Y12: =S12*(1-D12)*(1-H12)*p_progression -> 11.909406 | Z12: =X12+Y12 -> 17.202475 | AA12: =T12*(1-D12)*p_death_advanced -> 3.5400315 | AB12: =(R12+S12)*G12 -> 0 | AC12: =G12*(R12*(1-screen_specificity)+S12*screen_sensitivity) -> 0 | AD12: =AB12*cost_screen_test+AC12*cost_followup_test -> 0 | AE12: =X12*cost_early_treatment -> 79396.037 | AF12: =T12*cost_advanced_year -> 283627.96 | AG12: =AD12+AE12+AF12 -> 363024 | AH12: =V12 -> 99549.213 | AI12: =R12*u_healthy+S12*u_early+T12*u_advanced -> 89586.677 | AJ12: =1/(1+disc_costs)^A12 -> 0.91514166 | AK12: =1/(1+disc_effects)^A12 -> 0.91514166 | AL12: =AG12*AJ12 -> 332218.38 | AM12: =AI12*AK12 -> 81984.5 | AN12: =AH12*AK12 -> 91101.632 | AO12: =IF(AND(ABS(V12+U12-cohort_size)<0.000001*cohort_size,MIN(I12:Q12)>=0,MAX(I12:Q12)<=1),"OK","CHECK") -> OK
A13: =A12+1 -> 4 | B13: =start_age+A13 -> 44 | C13: =INDEX(age_band_label,MATCH(B13,age_band_start,1)) -> 40-44 | D13: =INDEX(p_background_death,MATCH(B13,age_band_start,1)) -> 0.0015 | E13: =INDEX(p_cancer_onset,MATCH(B13,age_band_start,1)) -> 0.00025 | F13: =IF(AND($B$3="Yes",B13>=$E$3,B13<=$H$3),1,0) -> 0 | G13: =F13*screen_participation -> 0 | H13: =1-(1-p_detect_symptoms)*(1-G13*screen_sensitivity) -> 0.1 | I13: =1-J13-K13 -> 0.99825038 | J13: =(1-D13)*E13 -> 0.000249625 | K13: =D13 -> 0.0015 | L13: =(1-D13)*H13*p_cure_early -> 0.089865 | M13: =(1-D13)*(1-H13)*(1-p_progression) -> 0.6739875 | N13: =(1-D13)*(H13*(1-p_cure_early)+(1-H13)*p_progression) -> 0.2346475 | O13: =D13 -> 0.0015 | P13: =1-Q13 -> 0.748875 | Q13: =1-(1-D13)*(1-p_death_advanced) -> 0.251125 | R13: =R12*I12+S12*L12 -> 99312.728 | S13: =R12*J12+S12*M12 -> 60.561416 | T13: =S12*N12+T12*P12 -> 23.058807 | U13: =U12+R12*K12+S12*O12+T12*Q12 -> 603.65134 | V13: =R13+S13+T13 -> 99396.349 | W13: =R13*J13 -> 24.79094 | X13: =S13*(1-D13)*H13 -> 6.0470574 | Y13: =S13*(1-D13)*(1-H13)*p_progression -> 13.605879 | Z13: =X13+Y13 -> 19.652937 | AA13: =T13*(1-D13)*p_death_advanced -> 5.7560547 | AB13: =(R13+S13)*G13 -> 0 | AC13: =G13*(R13*(1-screen_specificity)+S13*screen_sensitivity) -> 0 | AD13: =AB13*cost_screen_test+AC13*cost_followup_test -> 0 | AE13: =X13*cost_early_treatment -> 90705.861 | AF13: =T13*cost_advanced_year -> 461176.14 | AG13: =AD13+AE13+AF13 -> 551882 | AH13: =V13 -> 99396.349 | AI13: =R13*u_healthy+S13*u_early+T13*u_advanced -> 89445.615 | AJ13: =1/(1+disc_costs)^A13 -> 0.88848705 | AK13: =1/(1+disc_effects)^A13 -> 0.88848705 | AL13: =AG13*AJ13 -> 490340.01 | AM13: =AI13*AK13 -> 79471.271 | AN13: =AH13*AK13 -> 88312.368 | AO13: =IF(AND(ABS(V13+U13-cohort_size)<0.000001*cohort_size,MIN(I13:Q13)>=0,MAX(I13:Q13)<=1),"OK","CHECK") -> OK
A14: =A13+1 -> 5 | B14: =start_age+A14 -> 45 | C14: =INDEX(age_band_label,MATCH(B14,age_band_start,1)) -> 45-49 | D14: =INDEX(p_background_death,MATCH(B14,age_band_start,1)) -> 0.0023 | E14: =INDEX(p_cancer_onset,MATCH(B14,age_band_start,1)) -> 0.00035 | F14: =IF(AND($B$3="Yes",B14>=$E$3,B14<=$H$3),1,0) -> 0 | G14: =F14*screen_participation -> 0 | H14: =1-(1-p_detect_symptoms)*(1-G14*screen_sensitivity) -> 0.1 | I14: =1-J14-K14 -> 0.99735081 | J14: =(1-D14)*E14 -> 0.000349195 | K14: =D14 -> 0.0023 | L14: =(1-D14)*H14*p_cure_early -> 0.089793 | M14: =(1-D14)*(1-H14)*(1-p_progression) -> 0.6734475 | N14: =(1-D14)*(H14*(1-p_cure_early)+(1-H14)*p_progression) -> 0.2344595 | O14: =D14 -> 0.0023 | P14: =1-Q14 -> 0.748275 | Q14: =1-(1-D14)*(1-p_death_advanced) -> 0.251725 | R14: =R13*I13+S13*L13 -> 99144.411 | S14: =R13*J13+S13*M13 -> 65.608577 | T14: =S13*N13+T13*P13 -> 31.478749 | U14: =U13+R13*K13+S13*O13+T13*Q13 -> 758.50192 | V14: =R14+S14+T14 -> 99241.498 | W14: =R14*J14 -> 34.620733 | X14: =S14*(1-D14)*H14 -> 6.5457678 | Y14: =S14*(1-D14)*(1-H14)*p_progression -> 14.727977 | Z14: =X14+Y14 -> 21.273745 | AA14: =T14*(1-D14)*p_death_advanced -> 7.851587 | AB14: =(R14+S14)*G14 -> 0 | AC14: =G14*(R14*(1-screen_specificity)+S14*screen_sensitivity) -> 0 | AD14: =AB14*cost_screen_test+AC14*cost_followup_test -> 0 | AE14: =X14*cost_early_treatment -> 98186.517 | AF14: =T14*cost_advanced_year -> 629574.98 | AG14: =AD14+AE14+AF14 -> 727761.5 | AH14: =V14 -> 99241.498 | AI14: =R14*u_healthy+S14*u_early+T14*u_advanced -> 89303.05 | AJ14: =1/(1+disc_costs)^A14 -> 0.86260878 | AK14: =1/(1+disc_effects)^A14 -> 0.86260878 | AL14: =AG14*AJ14 -> 627773.46 | AM14: =AI14*AK14 -> 77033.596 | AN14: =AH14*AK14 -> 85606.588 | AO14: =IF(AND(ABS(V14+U14-cohort_size)<0.000001*cohort_size,MIN(I14:Q14)>=0,MAX(I14:Q14)<=1),"OK","CHECK") -> OK
